Workbook

Sheet 00_Inputs
C2: MODELO NEXUM - INPUTS DEL MANDATO
C3: Moneda funcional USD. Los porcentajes de cartera serán resultados del optimizador.
C5: Estado de la hoja | D5: =IF(AND(D17>0,D18>0,D24>0,D25>=0,D26>0,COUNTBLANK(E33:E36)=0),"COMPLETA PARA 01_FLUJOS","REVISAR INPUTS")
C7: Convención: amarillo = input editable; verde = fórmula; gris = política o dato descriptivo.
C9: 1. CONFIGURACIÓN DEL MODELO
C10: Parámetro | D10: Valor | E10: Unidad | F10: Clasificación | G10: Fuente | H10: Tratamiento
C11: Moneda funcional | D11: USD | E11: Moneda | F11: Política | G11: Informe Estrategia de Inversión, Grupo 11 | H11: Todos los cálculos se expresarán en USD
C12: Fecha de corte | D12: 46245 | E12: Fecha | F12: Input | G12: Confirmado por el usuario | H12: Fecha asociada a los tipos de cambio iniciales
C13: Escenario central | D13: Base contractual | E13: Escenario | F13: Política | G13: Caso e IPS | H13: 19 aportes; objetivos en dinero de hoy
C14: Base de medición | D14: USD reales | E14: Unidad | F14: Política | G14: Informe Estrategia de Inversión, Grupo 11 | H14: Dólares de la fecha de corte
C15: 2. TIPOS DE CAMBIO
C16: Parámetro | D16: Valor | E16: Unidad | F16: Clasificación | G16: Fuente | H16: Fórmula / tratamiento
C17: USD/CLP | D17: 911.77 | E17: CLP por USD | F17: Input | G17: Valor confirmado por el usuario | H17: Celda actualizable
C18: UF/CLP | D18: 40846 | E18: CLP por UF | F18: Input | G18: Valor confirmado por el usuario | H18: Celda actualizable
C19: USD por UF | D19: =D18/D17 | E19: USD por UF | F19: Calculado | G19: Derivado de tipos de cambio | H19: UF/CLP dividido por USD/CLP
C20: USD por CLP | D20: =1/D17 | E20: USD por CLP | F20: Calculado | G20: Derivado de USD/CLP | H20: Inverso de USD/CLP
C22: 3. CAPITAL Y APORTES
C23: Parámetro | D23: Valor | E23: Unidad | F23: Clasificación | G23: Fuente | H23: Tratamiento
C24: Capital inicial | D24: 150000 | E24: USD | F24: Dato del caso | G24: IPS, sección Perfil del Cliente | H24: Entrada en el año 0
C25: Aporte anual de Tomás | D25: 10000 | E25: USD | F25: Dato del caso | G25: IPS, sección Perfil del Cliente | H25: Aporte en abril de cada año
C26: Cantidad de aportes | D26: 19 | E26: Años | F26: Dato del caso | G26: IPS, sección Perfil del Cliente | H26: Escenario central contractual
C27: Primer año de aporte | D27: 1 | E27: Año | F27: Supuesto temporal | G27: Metodología del modelo | H27: Primer aporte posterior al capital inicial
C28: Mes del aporte | D28: Abril | E28: Mes | F28: Dato del caso | G28: IPS, sección Perfil del Cliente | H28: Se detallará al usar fechas exactas
C29: Aportes futuros sin capitalizar | D29: =D25*D26 | E29: USD | F29: Calculado | G29: Capital y aportes | H29: Aporte anual por cantidad de aportes
C31: 4. OBJETIVOS FINANCIEROS
C32: Prioridad | D32: Objetivo | E32: Monto original | F32: Moneda | G32: Primer año | H32: Último año | I32: N° pagos | J32: Total en USD | K32: Pago por evento USD | L32: Fuente / tratamiento
C33: 1 | D33: Educación Vicente | E33: 65000000 | F33: CLP | G33: 14 | H33: 18 | I33: 5 | J33: =E33/$D$17 | K33: =J33/I33 | L33: IPS: CLP 65 millones en dinero de hoy
C34: 1 | D34: Educación Emilia | E34: 65000000 | F34: CLP | G34: 16 | H34: 20 | I34: 5 | J34: =E34/$D$17 | K34: =J34/I34 | L34: IPS: CLP 65 millones en dinero de hoy
C35: 2 | D35: Propiedad en Villarrica | E35: 10500 | F35: UF | G35: 25 | H35: 25 | I35: 1 | J35: =E35*$D$19 | K35: =J35/I35 | L35: Desembolso adicional; el resto se financia con venta de la casa
C36: 3 | D36: Herencia familiar | E36: 500000 | F36: USD | G36: 50 | H36: 50 | I36: 1 | J36: =E36 | K36: =J36/I36 | L36: USD 250.000 por hijo
C38: Resumen sin descuento | D38: Valor | E38: Unidad | F38: Interpretación
C39: Educación total | D39: =SUM(J33:J34) | E39: USD | F39: Dos carreras completas
C40: Objetivos totales | D40: =SUM(J33:J36) | E40: USD | F40: Suma nominal real; no incorpora tiempos
C41: Capital más aportes | D41: =D24+D29 | E41: USD | F41: Suma sin capitalización; no mide suficiencia
C43: 5. RESTRICCIONES Y POLÍTICAS DEL IPS
C44: Restricción | D44: Valor | E44: Unidad | F44: Uso futuro | G44: Fuente | H44: Observación
C45: Tracking Error máximo cartera activa | D45: 0.04 | E45: % anual | F45: Optimizer / control | G45: IPS, Métricas de riesgo | H45: Se validará empíricamente
C46: Fondo de emergencia dentro del mandato | D46: No | E46: Política | F46: Flujos | G46: IPS, Escenarios de estrés | H46: La caja interna será liquidez operativa
C47: Instrumentos compatibles con StockTrak | D47: Sí | E47: Política | F47: Universo de activos | G47: IPS, Restricciones | H47: Condición de elegibilidad
C48: Uso puramente especulativo | D48: No permitido | E48: Política | F48: Universo de activos | G48: IPS, Restricciones | H48: Aplica a cortos, margen y derivados
...

Sheet 01_Flujos
C2: MODELO NEXUM - CALENDARIO DE FLUJOS
C3: Convención: entradas positivas; desembolsos negativos. Flujos anuales en USD reales.
C5: Total entradas | D5: =SUM(D10:E60) | F5: Total desembolsos | G5: =-SUM(F10:I60) | I5: Flujo neto sin descuento | J5: =SUM(J10:J60)
C6: Capital + aportes | D6: ='00_Inputs'!D41 | F6: Objetivos sin descuento | G6: ='00_Inputs'!D40 | I6: Horizonte | J6: 50
C8: FLUJOS DEL ESCENARIO CENTRAL | N8: CONTROLES DE RECONCILIACIÓN
C9: Año | D9: Capital inicial | E9: Aporte anual | F9: Educación Vicente | G9: Educación Emilia | H9: Propiedad Villarrica | I9: Herencia | J9: Flujo neto | K9: Acumulado sin retorno | L9: Evento principal | N9: Control | O9: Flujos | P9: Inputs | Q9: Diferencia
C10: 0 | D10: =IF(C10=0,'00_Inputs'!$D$24,0) | E10: =IF(AND(C10>='00_Inputs'!$D$27,C10<'00_Inputs'!$D$27+'00_Inputs'!$D$26),'00_Inputs'!$D$25,0) | F10: =IF(AND(C10>='00_Inputs'!$G$33,C10<='00_Inputs'!$H$33),-'00_Inputs'!$K$33*(1+'00_Inputs'!$D$55)^C10,0) | G10: =IF(AND(C10>='00_Inputs'!$G$34,C10<='00_Inputs'!$H$34),-'00_Inputs'!$K$34*(1+'00_Inputs'!$D$55)^C10,0) | H10: =IF(C10='00_Inputs'!$G$35,-'00_Inputs'!$J$35,0) | I10: =IF(C10='00_Inputs'!$G$36,-'00_Inputs'!$J$36,0) | J10: =SUM(D10:I10) | K10: =J10 | L10: =IF(C10=0,"Capital inicial",IF(AND(F10<0,G10<0),"Educación de ambos hijos",IF(F10<0,"Educación Vicente",IF(G10<0,"Educación Emilia",IF(H10<0,"Compra Villarrica",IF(I10<0,"Pago herencia",IF(E10>0,"Aporte anual",""))))))) | N10: Capital inicial | O10: =SUM(D10:D60) | P10: ='00_Inputs'!D24 | Q10: =O10-P10
C11: 1 | D11: =IF(C11=0,'00_Inputs'!$D$24,0) | E11: =IF(AND(C11>='00_Inputs'!$D$27,C11<'00_Inputs'!$D$27+'00_Inputs'!$D$26),'00_Inputs'!$D$25,0) | F11: =IF(AND(C11>='00_Inputs'!$G$33,C11<='00_Inputs'!$H$33),-'00_Inputs'!$K$33*(1+'00_Inputs'!$D$55)^C11,0) | G11: =IF(AND(C11>='00_Inputs'!$G$34,C11<='00_Inputs'!$H$34),-'00_Inputs'!$K$34*(1+'00_Inputs'!$D$55)^C11,0) | H11: =IF(C11='00_Inputs'!$G$35,-'00_Inputs'!$J$35,0) | I11: =IF(C11='00_Inputs'!$G$36,-'00_Inputs'!$J$36,0) | J11: =SUM(D11:I11) | K11: =K10+J11 | L11: =IF(C11=0,"Capital inicial",IF(AND(F11<0,G11<0),"Educación de ambos hijos",IF(F11<0,"Educación Vicente",IF(G11<0,"Educación Emilia",IF(H11<0,"Compra Villarrica",IF(I11<0,"Pago herencia",IF(E11>0,"Aporte anual",""))))))) | N11: Aportes | O11: =SUM(E10:E60) | P11: ='00_Inputs'!D29 | Q11: =O11-P11
C12: 2 | D12: =IF(C12=0,'00_Inputs'!$D$24,0) | E12: =IF(AND(C12>='00_Inputs'!$D$27,C12<'00_Inputs'!$D$27+'00_Inputs'!$D$26),'00_Inputs'!$D$25,0) | F12: =IF(AND(C12>='00_Inputs'!$G$33,C12<='00_Inputs'!$H$33),-'00_Inputs'!$K$33*(1+'00_Inputs'!$D$55)^C12,0) | G12: =IF(AND(C12>='00_Inputs'!$G$34,C12<='00_Inputs'!$H$34),-'00_Inputs'!$K$34*(1+'00_Inputs'!$D$55)^C12,0) | H12: =IF(C12='00_Inputs'!$G$35,-'00_Inputs'!$J$35,0) | I12: =IF(C12='00_Inputs'!$G$36,-'00_Inputs'!$J$36,0) | J12: =SUM(D12:I12) | K12: =K11+J12 | L12: =IF(C12=0,"Capital inicial",IF(AND(F12<0,G12<0),"Educación de ambos hijos",IF(F12<0,"Educación Vicente",IF(G12<0,"Educación Emilia",IF(H12<0,"Compra Villarrica",IF(I12<0,"Pago herencia",IF(E12>0,"Aporte anual",""))))))) | N12: Educación | O12: =-SUM(F10:G60) | P12: ='00_Inputs'!D39 | Q12: =O12-P12
C13: 3 | D13: =IF(C13=0,'00_Inputs'!$D$24,0) | E13: =IF(AND(C13>='00_Inputs'!$D$27,C13<'00_Inputs'!$D$27+'00_Inputs'!$D$26),'00_Inputs'!$D$25,0) | F13: =IF(AND(C13>='00_Inputs'!$G$33,C13<='00_Inputs'!$H$33),-'00_Inputs'!$K$33*(1+'00_Inputs'!$D$55)^C13,0) | G13: =IF(AND(C13>='00_Inputs'!$G$34,C13<='00_Inputs'!$H$34),-'00_Inputs'!$K$34*(1+'00_Inputs'!$D$55)^C13,0) | H13: =IF(C13='00_Inputs'!$G$35,-'00_Inputs'!$J$35,0) | I13: =IF(C13='00_Inputs'!$G$36,-'00_Inputs'!$J$36,0) | J13: =SUM(D13:I13) | K13: =K12+J13 | L13: =IF(C13=0,"Capital inicial",IF(AND(F13<0,G13<0),"Educación de ambos hijos",IF(F13<0,"Educación Vicente",IF(G13<0,"Educación Emilia",IF(H13<0,"Compra Villarrica",IF(I13<0,"Pago herencia",IF(E13>0,"Aporte anual",""))))))) | N13: Propiedad | O13: =-SUM(H10:H60) | P13: ='00_Inputs'!J35 | Q13: =O13-P13
C14: 4 | D14: =IF(C14=0,'00_Inputs'!$D$24,0) | E14: =IF(AND(C14>='00_Inputs'!$D$27,C14<'00_Inputs'!$D$27+'00_Inputs'!$D$26),'00_Inputs'!$D$25,0) | F14: =IF(AND(C14>='00_Inputs'!$G$33,C14<='00_Inputs'!$H$33),-'00_Inputs'!$K$33*(1+'00_Inputs'!$D$55)^C14,0) | G14: =IF(AND(C14>='00_Inputs'!$G$34,C14<='00_Inputs'!$H$34),-'00_Inputs'!$K$34*(1+'00_Inputs'!$D$55)^C14,0) | H14: =IF(C14='00_Inputs'!$G$35,-'00_Inputs'!$J$35,0) | I14: =IF(C14='00_Inputs'!$G$36,-'00_Inputs'!$J$36,0) | J14: =SUM(D14:I14) | K14: =K13+J14 | L14: =IF(C14=0,"Capital inicial",IF(AND(F14<0,G14<0),"Educación de ambos hijos",IF(F14<0,"Educación Vicente",IF(G14<0,"Educación Emilia",IF(H14<0,"Compra Villarrica",IF(I14<0,"Pago herencia",IF(E14>0,"Aporte anual",""))))))) | N14: Herencia | O14: =-SUM(I10:I60) | P14: ='00_Inputs'!J36 | Q14: =O14-P14
C15: 5 | D15: =IF(C15=0,'00_Inputs'!$D$24,0) | E15: =IF(AND(C15>='00_Inputs'!$D$27,C15<'00_Inputs'!$D$27+'00_Inputs'!$D$26),'00_Inputs'!$D$25,0) | F15: =IF(AND(C15>='00_Inputs'!$G$33,C15<='00_Inputs'!$H$33),-'00_Inputs'!$K$33*(1+'00_Inputs'!$D$55)^C15,0) | G15: =IF(AND(C15>='00_Inputs'!$G$34,C15<='00_Inputs'!$H$34),-'00_Inputs'!$K$34*(1+'00_Inputs'!$D$55)^C15,0) | H15: =IF(C15='00_Inputs'!$G$35,-'00_Inputs'!$J$35,0) | I15: =IF(C15='00_Inputs'!$G$36,-'00_Inputs'!$J$36,0) | J15: =SUM(D15:I15) | K15: =K14+J15 | L15: =IF(C15=0,"Capital inicial",IF(AND(F15<0,G15<0),"Educación de ambos hijos",IF(F15<0,"Educación Vicente",IF(G15<0,"Educación Emilia",IF(H15<0,"Compra Villarrica",IF(I15<0,"Pago herencia",IF(E15>0,"Aporte anual",""))))))) | N15: Flujo neto | O15: =SUM(J10:J60) | P15: =SUM(D10:I60) | Q15: =O15-P15
C16: 6 | D16: =IF(C16=0,'00_Inputs'!$D$24,0) | E16: =IF(AND(C16>='00_Inputs'!$D$27,C16<'00_Inputs'!$D$27+'00_Inputs'!$D$26),'00_Inputs'!$D$25,0) | F16: =IF(AND(C16>='00_Inputs'!$G$33,C16<='00_Inputs'!$H$33),-'00_Inputs'!$K$33*(1+'00_Inputs'!$D$55)^C16,0) | G16: =IF(AND(C16>='00_Inputs'!$G$34,C16<='00_Inputs'!$H$34),-'00_Inputs'!$K$34*(1+'00_Inputs'!$D$55)^C16,0) | H16: =IF(C16='00_Inputs'!$G$35,-'00_Inputs'!$J$35,0) | I16: =IF(C16='00_Inputs'!$G$36,-'00_Inputs'!$J$36,0) | J16: =SUM(D16:I16) | K16: =K15+J16 | L16: =IF(C16=0,"Capital inicial",IF(AND(F16<0,G16<0),"Educación de ambos hijos",IF(F16<0,"Educación Vicente",IF(G16<0,"Educación Emilia",IF(H16<0,"Compra Villarrica",IF(I16<0,"Pago herencia",IF(E16>0,"Aporte anual","")))))))
C17: 7 | D17: =IF(C17=0,'00_Inputs'!$D$24,0) | E17: =IF(AND(C17>='00_Inputs'!$D$27,C17<'00_Inputs'!$D$27+'00_Inputs'!$D$26),'00_Inputs'!$D$25,0) | F17: =IF(AND(C17>='00_Inputs'!$G$33,C17<='00_Inputs'!$H$33),-'00_Inputs'!$K$33*(1+'00_Inputs'!$D$55)^C17,0) | G17: =IF(AND(C17>='00_Inputs'!$G$34,C17<='00_Inputs'!$H$34),-'00_Inputs'!$K$34*(1+'00_Inputs'!$D$55)^C17,0) | H17: =IF(C17='00_Inputs'!$G$35,-'00_Inputs'!$J$35,0) | I17: =IF(C17='00_Inputs'!$G$36,-'00_Inputs'!$J$36,0) | J17: =SUM(D17:I17) | K17: =K16+J17 | L17: =IF(C17=0,"Capital inicial",IF(AND(F17<0,G17<0),"Educación de ambos hijos",IF(F17<0,"Educación Vicente",IF(G17<0,"Educación Emilia",IF(H17<0,"Compra Villarrica",IF(I17<0,"Pago herencia",IF(E17>0,"Aporte anual","")))))))
C18: 8 | D18: =IF(C18=0,'00_Inputs'!$D$24,0) | E18: =IF(AND(C18>='00_Inputs'!$D$27,C18<'00_Inputs'!$D$27+'00_Inputs'!$D$26),'00_Inputs'!$D$25,0) | F18: =IF(AND(C18>='00_Inputs'!$G$33,C18<='00_Inputs'!$H$33),-'00_Inputs'!$K$33*(1+'00_Inputs'!$D$55)^C18,0) | G18: =IF(AND(C18>='00_Inputs'!$G$34,C18<='00_Inputs'!$H$34),-'00_Inputs'!$K$34*(1+'00_Inputs'!$D$55)^C18,0) | H18: =IF(C18='00_Inputs'!$G$35,-'00_Inputs'!$J$35,0) | I18: =IF(C18='00_Inputs'!$G$36,-'00_Inputs'!$J$36,0) | J18: =SUM(D18:I18) | K18: =K17+J18 | L18: =IF(C18=0,"Capital inicial",IF(AND(F18<0,G18<0),"Educación de ambos hijos",IF(F18<0,"Educación Vicente",IF(G18<0,"Educación Emilia",IF(H18<0,"Compra Villarrica",IF(I18<0,"Pago herencia",IF(E18>0,"Aporte anual",""))))))) | N18: SUPUESTOS DE TEMPORIZACIÓN
C19: 9 | D19: =IF(C19=0,'00_Inputs'!$D$24,0) | E19: =IF(AND(C19>='00_Inputs'!$D$27,C19<'00_Inputs'!$D$27+'00_Inputs'!$D$26),'00_Inputs'!$D$25,0) | F19: =IF(AND(C19>='00_Inputs'!$G$33,C19<='00_Inputs'!$H$33),-'00_Inputs'!$K$33*(1+'00_Inputs'!$D$55)^C19,0) | G19: =IF(AND(C19>='00_Inputs'!$G$34,C19<='00_Inputs'!$H$34),-'00_Inputs'!$K$34*(1+'00_Inputs'!$D$55)^C19,0) | H19: =IF(C19='00_Inputs'!$G$35,-'00_Inputs'!$J$35,0) | I19: =IF(C19='00_Inputs'!$G$36,-'00_Inputs'!$J$36,0) | J19: =SUM(D19:I19) | K19: =K18+J19 | L19: =IF(C19=0,"Capital inicial",IF(AND(F19<0,G19<0),"Educación de ambos hijos",IF(F19<0,"Educación Vicente",IF(G19<0,"Educación Emilia",IF(H19<0,"Compra Villarrica",IF(I19<0,"Pago herencia",IF(E19>0,"Aporte anual",""))))))) | N19: Frecuencia | O19: Anual | Q19: Misma convención que el Banco de Información
C20: 10 | D20: =IF(C20=0,'00_Inputs'!$D$24,0) | E20: =IF(AND(C20>='00_Inputs'!$D$27,C20<'00_Inputs'!$D$27+'00_Inputs'!$D$26),'00_Inputs'!$D$25,0) | F20: =IF(AND(C20>='00_Inputs'!$G$33,C20<='00_Inputs'!$H$33),-'00_Inputs'!$K$33*(1+'00_Inputs'!$D$55)^C20,0) | G20: =IF(AND(C20>='00_Inputs'!$G$34,C20<='00_Inputs'!$H$34),-'00_Inputs'!$K$34*(1+'00_Inputs'!$D$55)^C20,0) | H20: =IF(C20='00_Inputs'!$G$35,-'00_Inputs'!$J$35,0) | I20: =IF(C20='00_Inputs'!$G$36,-'00_Inputs'!$J$36,0) | J20: =SUM(D20:I20) | K20: =K19+J20 | L20: =IF(C20=0,"Capital inicial",IF(AND(F20<0,G20<0),"Educación de ambos hijos",IF(F20<0,"Educación Vicente",IF(G20<0,"Educación Emilia",IF(H20<0,"Compra Villarrica",IF(I20<0,"Pago herencia",IF(E20>0,"Aporte anual",""))))))) | N20: Momento del flujo | O20: Fin de año | Q20: Se usará IRR sobre años 0 a 50
C21: 11 | D21: =IF(C21=0,'00_Inputs'!$D$24,0) | E21: =IF(AND(C21>='00_Inputs'!$D$27,C21<'00_Inputs'!$D$27+'00_Inputs'!$D$26),'00_Inputs'!$D$25,0) | F21: =IF(AND(C21>='00_Inputs'!$G$33,C21<='00_Inputs'!$H$33),-'00_Inputs'!$K$33*(1+'00_Inputs'!$D$55)^C21,0) | G21: =IF(AND(C21>='00_Inputs'!$G$34,C21<='00_Inputs'!$H$34),-'00_Inputs'!$K$34*(1+'00_Inputs'!$D$55)^C21,0) | H21: =IF(C21='00_Inputs'!$G$35,-'00_Inputs'!$J$35,0) | I21: =IF(C21='00_Inputs'!$G$36,-'00_Inputs'!$J$36,0) | J21: =SUM(D21:I21) | K21: =K20+J21 | L21: =IF(C21=0,"Capital inicial",IF(AND(F21<0,G21<0),"Educación de ambos hijos",IF(F21<0,"Educación Vicente",IF(G21<0,"Educación Emilia",IF(H21<0,"Compra Villarrica",IF(I21<0,"Pago herencia",IF(E21>0,"Aporte anual",""))))))) | N21: Aportes | O21: Años 1 a 19 | Q21: USD 10.000 por año
C22: 12 | D22: =IF(C22=0,'00_Inputs'!$D$24,0) | E22: =IF(AND(C22>='00_Inputs'!$D$27,C22<'00_Inputs'!$D$27+'00_Inputs'!$D$26),'00_Inputs'!$D$25,0) | F22: =IF(AND(C22>='00_Inputs'!$G$33,C22<='00_Inputs'!$H$33),-'00_Inputs'!$K$33*(1+'00_Inputs'!$D$55)^C22,0) | G22: =IF(AND(C22>='00_Inputs'!$G$34,C22<='00_Inputs'!$H$34),-'00_Inputs'!$K$34*(1+'00_Inputs'!$D$55)^C22,0) | H22: =IF(C22='00_Inputs'!$G$35,-'00_Inputs'!$J$35,0) | I22: =IF(C22='00_Inputs'!$G$36,-'00_Inputs'!$J$36,0) | J22: =SUM(D22:I22) | K22: =K21+J22 | L22: =IF(C22=0,"Capital inicial",IF(AND(F22<0,G22<0),"Educación de ambos hijos",IF(F22<0,"Educación Vicente",IF(G22<0,"Educación Emilia",IF(H22<0,"Compra Villarrica",IF(I22<0,"Pago herencia",IF(E22>0,"Aporte anual",""))))))) | N22: Educación | O22: 5 pagos por hijo | Q22: Vicente 14-18; Emilia 16-20
C23: 13 | D23: =IF(C23=0,'00_Inputs'!$D$24,0) | E23: =IF(AND(C23>='00_Inputs'!$D$27,C23<'00_Inputs'!$D$27+'00_Inputs'!$D$26),'00_Inputs'!$D$25,0) | F23: =IF(AND(C23>='00_Inputs'!$G$33,C23<='00_Inputs'!$H$33),-'00_Inputs'!$K$33*(1+'00_Inputs'!$D$55)^C23,0) | G23: =IF(AND(C23>='00_Inputs'!$G$34,C23<='00_Inputs'!$H$34),-'00_Inputs'!$K$34*(1+'00_Inputs'!$D$55)^C23,0) | H23: =IF(C23='00_Inputs'!$G$35,-'00_Inputs'!$J$35,0) | I23: =IF(C23='00_Inputs'!$G$36,-'00_Inputs'!$J$36,0) | J23: =SUM(D23:I23) | K23: =K22+J23 | L23: =IF(C23=0,"Capital inicial",IF(AND(F23<0,G23<0),"Educación de ambos hijos",IF(F23<0,"Educación Vicente",IF(G23<0,"Educación Emilia",IF(H23<0,"Compra Villarrica",IF(I23<0,"Pago herencia",IF(E23>0,"Aporte anual","")))))))
C24: 14 | D24: =IF(C24=0,'00_Inputs'!$D$24,0) | E24: =IF(AND(C24>='00_Inputs'!$D$27,C24<'00_Inputs'!$D$27+'00_Inputs'!$D$26),'00_Inputs'!$D$25,0) | F24: =IF(AND(C24>='00_Inputs'!$G$33,C24<='00_Inputs'!$H$33),-'00_Inputs'!$K$33*(1+'00_Inputs'!$D$55)^C24,0) | G24: =IF(AND(C24>='00_Inputs'!$G$34,C24<='00_Inputs'!$H$34),-'00_Inputs'!$K$34*(1+'00_Inputs'!$D$55)^C24,0) | H24: =IF(C24='00_Inputs'!$G$35,-'00_Inputs'!$J$35,0) | I24: =IF(C24='00_Inputs'!$G$36,-'00_Inputs'!$J$36,0) | J24: =SUM(D24:I24) | K24: =K23+J24 | L24: =IF(C24=0,"Capital inicial",IF(AND(F24<0,G24<0),"Educación de ambos hijos",IF(F24<0,"Educación Vicente",IF(G24<0,"Educación Emilia",IF(H24<0,"Compra Villarrica",IF(I24<0,"Pago herencia",IF(E24>0,"Aporte anual","")))))))
C25: 15 | D25: =IF(C25=0,'00_Inputs'!$D$24,0) | E25: =IF(AND(C25>='00_Inputs'!$D$27,C25<'00_Inputs'!$D$27+'00_Inputs'!$D$26),'00_Inputs'!$D$25,0) | F25: =IF(AND(C25>='00_Inputs'!$G$33,C25<='00_Inputs'!$H$33),-'00_Inputs'!$K$33*(1+'00_Inputs'!$D$55)^C25,0) | G25: =IF(AND(C25>='00_Inputs'!$G$34,C25<='00_Inputs'!$H$34),-'00_Inputs'!$K$34*(1+'00_Inputs'!$D$55)^C25,0) | H25: =IF(C25='00_Inputs'!$G$35,-'00_Inputs'!$J$35,0) | I25: =IF(C25='00_Inputs'!$G$36,-'00_Inputs'!$J$36,0) | J25: =SUM(D25:I25) | K25: =K24+J25 | L25: =IF(C25=0,"Capital inicial",IF(AND(F25<0,G25<0),"Educación de ambos hijos",IF(F25<0,"Educación Vicente",IF(G25<0,"Educación Emilia",IF(H25<0,"Compra Villarrica",IF(I25<0,"Pago herencia",IF(E25>0,"Aporte anual","")))))))
C26: 16 | D26: =IF(C26=0,'00_Inputs'!$D$24,0) | E26: =IF(AND(C26>='00_Inputs'!$D$27,C26<'00_Inputs'!$D$27+'00_Inputs'!$D$26),'00_Inputs'!$D$25,0) | F26: =IF(AND(C26>='00_Inputs'!$G$33,C26<='00_Inputs'!$H$33),-'00_Inputs'!$K$33*(1+'00_Inputs'!$D$55)^C26,0) | G26: =IF(AND(C26>='00_Inputs'!$G$34,C26<='00_Inputs'!$H$34),-'00_Inputs'!$K$34*(1+'00_Inputs'!$D$55)^C26,0) | H26: =IF(C26='00_Inputs'!$G$35,-'00_Inputs'!$J$35,0) | I26: =IF(C26='00_Inputs'!$G$36,-'00_Inputs'!$J$36,0) | J26: =SUM(D26:I26) | K26: =K25+J26 | L26: =IF(C26=0,"Capital inicial",IF(AND(F26<0,G26<0),"Educación de ambos hijos",IF(F26<0,"Educación Vicente",IF(G26<0,"Educación Emilia",IF(H26<0,"Compra Villarrica",IF(I26<0,"Pago herencia",IF(E26>0,"Aporte anual","")))))))
C27: 17 | D27: =IF(C27=0,'00_Inputs'!$D$24,0) | E27: =IF(AND(C27>='00_Inputs'!$D$27,C27<'00_Inputs'!$D$27+'00_Inputs'!$D$26),'00_Inputs'!$D$25,0) | F27: =IF(AND(C27>='00_Inputs'!$G$33,C27<='00_Inputs'!$H$33),-'00_Inputs'!$K$33*(1+'00_Inputs'!$D$55)^C27,0) | G27: =IF(AND(C27>='00_Inputs'!$G$34,C27<='00_Inputs'!$H$34),-'00_Inputs'!$K$34*(1+'00_Inputs'!$D$55)^C27,0) | H27: =IF(C27='00_Inputs'!$G$35,-'00_Inputs'!$J$35,0) | I27: =IF(C27='00_Inputs'!$G$36,-'00_Inputs'!$J$36,0) | J27: =SUM(D27:I27) | K27: =K26+J27 | L27: =IF(C27=0,"Capital inicial",IF(AND(F27<0,G27<0),"Educación de ambos hijos",IF(F27<0,"Educación Vicente",IF(G27<0,"Educación Emilia",IF(H27<0,"Compra Villarrica",IF(I27<0,"Pago herencia",IF(E27>0,"Aporte anual","")))))))
C28: 18 | D28: =IF(C28=0,'00_Inputs'!$D$24,0) | E28: =IF(AND(C28>='00_Inputs'!$D$27,C28<'00_Inputs'!$D$27+'00_Inputs'!$D$26),'00_Inputs'!$D$25,0) | F28: =IF(AND(C28>='00_Inputs'!$G$33,C28<='00_Inputs'!$H$33),-'00_Inputs'!$K$33*(1+'00_Inputs'!$D$55)^C28,0) | G28: =IF(AND(C28>='00_Inputs'!$G$34,C28<='00_Inputs'!$H$34),-'00_Inputs'!$K$34*(1+'00_Inputs'!$D$55)^C28,0) | H28: =IF(C28='00_Inputs'!$G$35,-'00_Inputs'!$J$35,0) | I28: =IF(C28='00_Inputs'!$G$36,-'00_Inputs'!$J$36,0) | J28: =SUM(D28:I28) | K28: =K27+J28 | L28: =IF(C28=0,"Capital inicial",IF(AND(F28<0,G28<0),"Educación de ambos hijos",IF(F28<0,"Educación Vicente",IF(G28<0,"Educación Emilia",IF(H28<0,"Compra Villarrica",IF(I28<0,"Pago herencia",IF(E28>0,"Aporte anual","")))))))
C29: 19 | D29: =IF(C29=0,'00_Inputs'!$D$24,0) | E29: =IF(AND(C29>='00_Inputs'!$D$27,C29<'00_Inputs'!$D$27+'00_Inputs'!$D$26),'00_Inputs'!$D$25,0) | F29: =IF(AND(C29>='00_Inputs'!$G$33,C29<='00_Inputs'!$H$33),-'00_Inputs'!$K$33*(1+'00_Inputs'!$D$55)^C29,0) | G29: =IF(AND(C29>='00_Inputs'!$G$34,C29<='00_Inputs'!$H$34),-'00_Inputs'!$K$34*(1+'00_Inputs'!$D$55)^C29,0) | H29: =IF(C29='00_Inputs'!$G$35,-'00_Inputs'!$J$35,0) | I29: =IF(C29='00_Inputs'!$G$36,-'00_Inputs'!$J$36,0) | J29: =SUM(D29:I29) | K29: =K28+J29 | L29: =IF(C29=0,"Capital inicial",IF(AND(F29<0,G29<0),"Educación de ambos hijos",IF(F29<0,"Educación Vicente",IF(G29<0,"Educación Emilia",IF(H29<0,"Compra Villarrica",IF(I29<0,"Pago herencia",IF(E29>0,"Aporte anual","")))))))
C30: 20 | D30: =IF(C30=0,'00_Inputs'!$D$24,0) | E30: =IF(AND(C30>='00_Inputs'!$D$27,C30<'00_Inputs'!$D$27+'00_Inputs'!$D$26),'00_Inputs'!$D$25,0) | F30: =IF(AND(C30>='00_Inputs'!$G$33,C30<='00_Inputs'!$H$33),-'00_Inputs'!$K$33*(1+'00_Inputs'!$D$55)^C30,0) | G30: =IF(AND(C30>='00_Inputs'!$G$34,C30<='00_Inputs'!$H$34),-'00_Inputs'!$K$34*(1+'00_Inputs'!$D$55)^C30,0) | H30: =IF(C30='00_Inputs'!$G$35,-'00_Inputs'!$J$35,0) | I30: =IF(C30='00_Inputs'!$G$36,-'00_Inputs'!$J$36,0) | J30: =SUM(D30:I30) | K30: =K29+J30 | L30: =IF(C30=0,"Capital inicial",IF(AND(F30<0,G30<0),"Educación de ambos hijos",IF(F30<0,"Educación Vicente",IF(G30<0,"Educación Emilia",IF(H30<0,"Compra Villarrica",IF(I30<0,"Pago herencia",IF(E30>0,"Aporte anual","")))))))
C31: 21 | D31: =IF(C31=0,'00_Inputs'!$D$24,0) | E31: =IF(AND(C31>='00_Inputs'!$D$27,C31<'00_Inputs'!$D$27+'00_Inputs'!$D$26),'00_Inputs'!$D$25,0) | F31: =IF(AND(C31>='00_Inputs'!$G$33,C31<='00_Inputs'!$H$33),-'00_Inputs'!$K$33*(1+'00_Inputs'!$D$55)^C31,0) | G31: =IF(AND(C31>='00_Inputs'!$G$34,C31<='00_Inputs'!$H$34),-'00_Inputs'!$K$34*(1+'00_Inputs'!$D$55)^C31,0) | H31: =IF(C31='00_Inputs'!$G$35,-'00_Inputs'!$J$35,0) | I31: =IF(C31='00_Inputs'!$G$36,-'00_Inputs'!$J$36,0) | J31: =SUM(D31:I31) | K31: =K30+J31 | L31: =IF(C31=0,"Capital inicial",IF(AND(F31<0,G31<0),"Educación de ambos hijos",IF(F31<0,"Educación Vicente",IF(G31<0,"Educación Emilia",IF(H31<0,"Compra Villarrica",IF(I31<0,"Pago herencia",IF(E31>0,"Aporte anual","")))))))
C32: 22 | D32: =IF(C32=0,'00_Inputs'!$D$24,0) | E32: =IF(AND(C32>='00_Inputs'!$D$27,C32<'00_Inputs'!$D$27+'00_Inputs'!$D$26),'00_Inputs'!$D$25,0) | F32: =IF(AND(C32>='00_Inputs'!$G$33,C32<='00_Inputs'!$H$33),-'00_Inputs'!$K$33*(1+'00_Inputs'!$D$55)^C32,0) | G32: =IF(AND(C32>='00_Inputs'!$G$34,C32<='00_Inputs'!$H$34),-'00_Inputs'!$K$34*(1+'00_Inputs'!$D$55)^C32,0) | H32: =IF(C32='00_Inputs'!$G$35,-'00_Inputs'!$J$35,0) | I32: =IF(C32='00_Inputs'!$G$36,-'00_Inputs'!$J$36,0) | J32: =SUM(D32:I32) | K32: =K31+J32 | L32: =IF(C32=0,"Capital inicial",IF(AND(F32<0,G32<0),"Educación de ambos hijos",IF(F32<0,"Educación Vicente",IF(G32<0,"Educación Emilia",IF(H32<0,"Compra Villarrica",IF(I32<0,"Pago herencia",IF(E32>0,"Aporte anual","")))))))
C33: 23 | D33: =IF(C33=0,'00_Inputs'!$D$24,0) | E33: =IF(AND(C33>='00_Inputs'!$D$27,C33<'00_Inputs'!$D$27+'00_Inputs'!$D$26),'00_Inputs'!$D$25,0) | F33: =IF(AND(C33>='00_Inputs'!$G$33,C33<='00_Inputs'!$H$33),-'00_Inputs'!$K$33*(1+'00_Inputs'!$D$55)^C33,0) | G33: =IF(AND(C33>='00_Inputs'!$G$34,C33<='00_Inputs'!$H$34),-'00_Inputs'!$K$34*(1+'00_Inputs'!$D$55)^C33,0) | H33: =IF(C33='00_Inputs'!$G$35,-'00_Inputs'!$J$35,0) | I33: =IF(C33='00_Inputs'!$G$36,-'00_Inputs'!$J$36,0) | J33: =SUM(D33:I33) | K33: =K32+J33 | L33: =IF(C33=0,"Capital inicial",IF(AND(F33<0,G33<0),"Educación de ambos hijos",IF(F33<0,"Educación Vicente",IF(G33<0,"Educación Emilia",IF(H33<0,"Compra Villarrica",IF(I33<0,"Pago herencia",IF(E33>0,"Aporte anual","")))))))
C34: 24 | D34: =IF(C34=0,'00_Inputs'!$D$24,0) | E34: =IF(AND(C34>='00_Inputs'!$D$27,C34<'00_Inputs'!$D$27+'00_Inputs'!$D$26),'00_Inputs'!$D$25,0) | F34: =IF(AND(C34>='00_Inputs'!$G$33,C34<='00_Inputs'!$H$33),-'00_Inputs'!$K$33*(1+'00_Inputs'!$D$55)^C34,0) | G34: =IF(AND(C34>='00_Inputs'!$G$34,C34<='00_Inputs'!$H$34),-'00_Inputs'!$K$34*(1+'00_Inputs'!$D$55)^C34,0) | H34: =IF(C34='00_Inputs'!$G$35,-'00_Inputs'!$J$35,0) | I34: =IF(C34='00_Inputs'!$G$36,-'00_Inputs'!$J$36,0) | J34: =SUM(D34:I34) | K34: =K33+J34 | L34: =IF(C34=0,"Capital inicial",IF(AND(F34<0,G34<0),"Educación de ambos hijos",IF(F34<0,"Educación Vicente",IF(G34<0,"Educación Emilia",IF(H34<0,"Compra Villarrica",IF(I34<0,"Pago herencia",IF(E34>0,"Aporte anual","")))))))
... C60: 50 | D60: =IF(C60=0,'00_Inputs'!$D$24,0) | E60: =IF(AND(C60>='00_Inputs'!$D$27,C60<'00_Inputs'!$D$27+'00_Inputs'!$D$26),'00_Inputs'!$D$25,0) | F60: =IF(AND(C60>='00_Inputs'!$G$33,C60<='00_Inputs'!$H$33),-'00_Inputs'!$K$33*(1+'00_Inputs'!$D$55)^C60,0) | G60: =IF(AND(C60>='00_Inputs'!$G$34,C60<='00_Inputs'!$H$34),-'00_Inputs'!$K$34*(1+'00_Inputs'!$D$55)^C60,0) | H60: =IF(C60='00_Inputs'!$G$35,-'00_Inputs'!$J$35,0) | I60: =IF(C60='00_Inputs'!$G$36,-'00_Inputs'!$J$36,0) | J60: =SUM(D60:I60) | K60: =K59+J60 | L60: =IF(C60=0,"Capital inicial",IF(AND(F60<0,G60<0),"Educación de ambos hijos",IF(F60<0,"Educación Vicente",IF(G60<0,"Educación Emilia",IF(H60<0,"Compra Villarrica",IF(I60<0,"Pago herencia",IF(E60>0,"Aporte anual","")))))))

Sheet 02_TIR_Objetivos
C2: MODELO NEXUM - RETORNOS MÍNIMOS REQUERIDOS
C3: Las tasas resuelven VPN = 0. No son retornos esperados ni garantizados de la cartera.
C5: 1. TIR GLOBAL DEL MANDATO | H5: 2. FONDEO LDI DE EDUCACIÓN | N5: CONTROLES
C6: TIR real requerida | D6: =IRR('01_Flujos'!J10:J60,0.045) | E6: % anual | F6: IRR de todos los flujos | H6: Tasa real LDI de referencia | I6: ='00_Inputs'!D72 | J6: % anual | K6: Proxy provisional | L6: Fisher: Treasury e inflación | N6: Control | O6: Resultado | P6: Tolerancia | Q6: Estado
C7: VP de entradas | D7: =SUM(G23:G73) | E7: USD | F7: Descontado a la TIR global | H7: Capital requerido hoy | I7: =SUM(J23:J73) | J7: USD | K7: VP de los diez pagos | L7: Resultado del modelo | N7: VPN global | O7: =D9 | P7: 0.01 | Q7: =IF(ABS(O7)<=P7,"OK","ERROR")
C8: VP de desembolsos | D8: =SUM(H23:H73) | E8: USD | F8: Descontado a la TIR global | H8: Participación implícita inicial | I8: =I7/'00_Inputs'!D24 | J8: % capital inicial | K8: No es un peso prefijado | L8: Capital LDI / capital inicial | N8: VP entradas vs salidas | O8: =D7-D8 | P8: 0.01 | Q8: =IF(ABS(O8)<=P8,"OK","ERROR")
C9: Diferencia de VP | D9: =D7-D8 | E9: USD | F9: Debe ser 0 | H9: Capital inicial residual | I9: ='00_Inputs'!D24-I7 | J9: USD | K9: Capital para crecimiento | L9: Capital inicial menos LDI | N9: Funding educación | O9: =I10-1 | P9: 1e-06 | Q9: =IF(ABS(O9)<=P9,"OK","ERROR")
C10: Lectura | D10: =IF(ABS(D9)<0.01,"EQUILIBRIO VERIFICADO","REVISAR") | F10: Tasa de equilibrio del plan completo | H10: Funding ratio inicial | I10: =I7/I7 | J10: x | K10: Capital asignado / VP educación | L10: Debe ser 1,00x | N10: VPN crecimiento | O10: =D17 | P10: 0.01 | Q10: =IF(ABS(O10)<=P10,"OK","ERROR")
H11: Estado tasa LDI | I11: ='00_Inputs'!D73 | K11: Pendiente de validación | L11: Se revisará con curva e instrumentos | N11: Capital inicial asignado | O11: =I7+I9-'00_Inputs'!D24 | P11: 0.01 | Q11: =IF(ABS(O11)<=P11,"OK","ERROR")
C12: 3. BLOQUE DE CRECIMIENTO | N12: Tasas positivas | O12: =MIN(D6,I6,D16) | P12: 0 | Q12: =IF(O12>0,"OK","ERROR")
C13: Capital inicial residual | D13: =I9 | E13: USD | F13: Después de prefinanciar educación
C14: Aportes asignados | D14: ='00_Inputs'!D29 | E14: USD | F14: 19 aportes contractuales
C15: Objetivos financiados | D15: ='00_Inputs'!J35+'00_Inputs'!J36 | E15: USD | F15: Propiedad más herencia | N15: LECTURA METODOLÓGICA
C16: TIR real mínima del bloque | D16: =IRR(K23:K73,0.05) | E16: % anual | F16: IRR del flujo de crecimiento | N16: TIR global | O16: =D6 | Q16: Tasa de equilibrio de todos los flujos
C17: VPN del bloque a su TIR | D17: =SUM(L23:L73) | E17: USD | F17: Debe ser 0 | N17: Tasa LDI | O17: =I6 | Q17: Tasa de descuento provisional; no es output del IRR
C18: Diferencia frente a TIR global | D18: =(D16-D6)*100 | E18: p.p. | F18: Exigencia adicional del bloque | N18: Participación LDI | O18: =I8 | Q18: Resultado del VP de educación / capital inicial
N19: TIR crecimiento | O19: =D16 | Q19: Hurdle para propiedad y herencia con aportes
C21: COMPROBACIÓN DE VALOR PRESENTE POR AÑO
C22: Año | D22: Flujo global | E22: Factor descuento | F22: VP global | G22: VP entradas | H22: VP desembolsos | I22: Flujo educación | J22: VP educación | K22: Flujo crecimiento | L22: VP crecimiento
C23: ='01_Flujos'!C10 | D23: ='01_Flujos'!J10 | E23: =1/(1+$D$6)^C23 | F23: =D23*E23 | G23: =IF(F23>0,F23,0) | H23: =IF(F23<0,-F23,0) | I23: ='01_Flujos'!F10+'01_Flujos'!G10 | J23: =-I23/(1+$I$6)^C23 | K23: =$I$9 | L23: =K23/(1+$D$16)^C23
C24: ='01_Flujos'!C11 | D24: ='01_Flujos'!J11 | E24: =1/(1+$D$6)^C24 | F24: =D24*E24 | G24: =IF(F24>0,F24,0) | H24: =IF(F24<0,-F24,0) | I24: ='01_Flujos'!F11+'01_Flujos'!G11 | J24: =-I24/(1+$I$6)^C24 | K24: ='01_Flujos'!E11+'01_Flujos'!H11+'01_Flujos'!I11 | L24: =K24/(1+$D$16)^C24
C25: ='01_Flujos'!C12 | D25: ='01_Flujos'!J12 | E25: =1/(1+$D$6)^C25 | F25: =D25*E25 | G25: =IF(F25>0,F25,0) | H25: =IF(F25<0,-F25,0) | I25: ='01_Flujos'!F12+'01_Flujos'!G12 | J25: =-I25/(1+$I$6)^C25 | K25: ='01_Flujos'!E12+'01_Flujos'!H12+'01_Flujos'!I12 | L25: =K25/(1+$D$16)^C25
C26: ='01_Flujos'!C13 | D26: ='01_Flujos'!J13 | E26: =1/(1+$D$6)^C26 | F26: =D26*E26 | G26: =IF(F26>0,F26,0) | H26: =IF(F26<0,-F26,0) | I26: ='01_Flujos'!F13+'01_Flujos'!G13 | J26: =-I26/(1+$I$6)^C26 | K26: ='01_Flujos'!E13+'01_Flujos'!H13+'01_Flujos'!I13 | L26: =K26/(1+$D$16)^C26
C27: ='01_Flujos'!C14 | D27: ='01_Flujos'!J14 | E27: =1/(1+$D$6)^C27 | F27: =D27*E27 | G27: =IF(F27>0,F27,0) | H27: =IF(F27<0,-F27,0) | I27: ='01_Flujos'!F14+'01_Flujos'!G14 | J27: =-I27/(1+$I$6)^C27 | K27: ='01_Flujos'!E14+'01_Flujos'!H14+'01_Flujos'!I14 | L27: =K27/(1+$D$16)^C27
C28: ='01_Flujos'!C15 | D28: ='01_Flujos'!J15 | E28: =1/(1+$D$6)^C28 | F28: =D28*E28 | G28: =IF(F28>0,F28,0) | H28: =IF(F28<0,-F28,0) | I28: ='01_Flujos'!F15+'01_Flujos'!G15 | J28: =-I28/(1+$I$6)^C28 | K28: ='01_Flujos'!E15+'01_Flujos'!H15+'01_Flujos'!I15 | L28: =K28/(1+$D$16)^C28
C29: ='01_Flujos'!C16 | D29: ='01_Flujos'!J16 | E29: =1/(1+$D$6)^C29 | F29: =D29*E29 | G29: =IF(F29>0,F29,0) | H29: =IF(F29<0,-F29,0) | I29: ='01_Flujos'!F16+'01_Flujos'!G16 | J29: =-I29/(1+$I$6)^C29 | K29: ='01_Flujos'!E16+'01_Flujos'!H16+'01_Flujos'!I16 | L29: =K29/(1+$D$16)^C29
C30: ='01_Flujos'!C17 | D30: ='01_Flujos'!J17 | E30: =1/(1+$D$6)^C30 | F30: =D30*E30 | G30: =IF(F30>0,F30,0) | H30: =IF(F30<0,-F30,0) | I30: ='01_Flujos'!F17+'01_Flujos'!G17 | J30: =-I30/(1+$I$6)^C30 | K30: ='01_Flujos'!E17+'01_Flujos'!H17+'01_Flujos'!I17 | L30: =K30/(1+$D$16)^C30
C31: ='01_Flujos'!C18 | D31: ='01_Flujos'!J18 | E31: =1/(1+$D$6)^C31 | F31: =D31*E31 | G31: =IF(F31>0,F31,0) | H31: =IF(F31<0,-F31,0) | I31: ='01_Flujos'!F18+'01_Flujos'!G18 | J31: =-I31/(1+$I$6)^C31 | K31: ='01_Flujos'!E18+'01_Flujos'!H18+'01_Flujos'!I18 | L31: =K31/(1+$D$16)^C31
C32: ='01_Flujos'!C19 | D32: ='01_Flujos'!J19 | E32: =1/(1+$D$6)^C32 | F32: =D32*E32 | G32: =IF(F32>0,F32,0) | H32: =IF(F32<0,-F32,0) | I32: ='01_Flujos'!F19+'01_Flujos'!G19 | J32: =-I32/(1+$I$6)^C32 | K32: ='01_Flujos'!E19+'01_Flujos'!H19+'01_Flujos'!I19 | L32: =K32/(1+$D$16)^C32
C33: ='01_Flujos'!C20 | D33: ='01_Flujos'!J20 | E33: =1/(1+$D$6)^C33 | F33: =D33*E33 | G33: =IF(F33>0,F33,0) | H33: =IF(F33<0,-F33,0) | I33: ='01_Flujos'!F20+'01_Flujos'!G20 | J33: =-I33/(1+$I$6)^C33 | K33: ='01_Flujos'!E20+'01_Flujos'!H20+'01_Flujos'!I20 | L33: =K33/(1+$D$16)^C33
C34: ='01_Flujos'!C21 | D34: ='01_Flujos'!J21 | E34: =1/(1+$D$6)^C34 | F34: =D34*E34 | G34: =IF(F34>0,F34,0) | H34: =IF(F34<0,-F34,0) | I34: ='01_Flujos'!F21+'01_Flujos'!G21 | J34: =-I34/(1+$I$6)^C34 | K34: ='01_Flujos'!E21+'01_Flujos'!H21+'01_Flujos'!I21 | L34: =K34/(1+$D$16)^C34
C35: ='01_Flujos'!C22 | D35: ='01_Flujos'!J22 | E35: =1/(1+$D$6)^C35 | F35: =D35*E35 | G35: =IF(F35>0,F35,0) | H35: =IF(F35<0,-F35,0) | I35: ='01_Flujos'!F22+'01_Flujos'!G22 | J35: =-I35/(1+$I$6)^C35 | K35: ='01_Flujos'!E22+'01_Flujos'!H22+'01_Flujos'!I22 | L35: =K35/(1+$D$16)^C35
... C73: ='01_Flujos'!C60 | D73: ='01_Flujos'!J60 | E73: =1/(1+$D$6)^C73 | F73: =D73*E73 | G73: =IF(F73>0,F73,0) | H73: =IF(F73<0,-F73,0) | I73: ='01_Flujos'!F60+'01_Flujos'!G60 | J73: =-I73/(1+$I$6)^C73 | K73: ='01_Flujos'!E60+'01_Flujos'!H60+'01_Flujos'!I60 | L73: =K73/(1+$D$16)^C73

Sheet 03_LDI_Educacion
C2: MODELO NEXUM - LDI E INMUNIZACIÓN DE EDUCACIÓN
C3: Se evalúan valor presente, duración, convexidad, riesgo cambiario y factibilidad de calce.
C5: 1. PASIVO EDUCACIONAL | H5: 2. FACTIBILIDAD DEL CALCE
C6: Tasa real de descuento | D6: ='00_Inputs'!D72 | E6: % anual | F6: Proxy provisional LDI | H6: Duración modificada del pasivo | I6: =D9 | J6: Objetivo de sensibilidad a tasas
C7: Valor presente | D7: =SUM(H33:H39) | E7: USD | F7: Diez pagos educacionales | H7: Mayor duración LDI disponible | I7: =MAX(F17:F21) | J7: Máximo entre instrumentos elegibles
C8: Duración Macaulay | D8: =SUM(I33:I39)/D7 | E8: Años | F8: Promedio temporal ponderado por VP | H8: Brecha de duración | I8: =I7-I6 | J8: Activo máximo menos pasivo
C9: Duración modificada | D9: =D8/(1+D6) | E9: Años | F9: Sensibilidad aproximada a tasas | H9: Calce exacto factible | I9: =IF(I8>=0,"POSIBLE POR DURACIÓN","NO FACTIBLE CON VCLT/TLH/MM") | J9: Evaluación con instrumentos actuales
C10: Convexidad | D10: =SUM(J33:J39)/D7 | E10: Índice | F10: Curvatura del precio del pasivo | H10: Moneda de los pasivos | I10: CLP | J10: Obligación educacional local
C11: Capital asignado | D11: ='02_TIR_Objetivos'!I7 | E11: USD | F11: Capital requerido calculado | H11: Moneda de los activos LDI | I11: USD | J11: VCLT, TLH y Money Market
C12: Funding ratio | D12: =D11/D7 | E12: x | F12: Capital asignado / valor presente | H12: Riesgo cambiario | I12: ABIERTO | J12: Requiere cobertura o calce natural
C15: 3. INSTRUMENTOS CONSIDERADOS
C16: Componente | D16: Ticker | E16: Elegible LDI | F16: Duración efectiva | G16: Moneda | H16: Riesgo principal | I16: Fuente / fecha | J16: Estado | L16: Shock | M16: Tasa real | N16: VP educación | O16: Funding ratio | P16: Superávit / déficit
C17: Bonos corporativos largos | D17: VCLT | E17: Sí | F17: 13 | G17: USD | H17: Tasa + spread de crédito | I17: Estructura_Portafolio.pdf | J17: Provisional; actualizar con factsheet | L17: -0.02 | M17: =$D$6+L17 | N17: =SUMPRODUCT($F$33:$F$39/(1+M17)^$C$33:$C$39) | O17: =$D$11/N17 | P17: =$D$11-N17
C18: Treasuries 10-20 años | D18: TLH | E18: Sí | F18: 11.71 | G18: USD | H18: Tasa soberana | I18: iShares, 09-09-2026 | J18: Fuente oficial | L18: -0.01 | M18: =$D$6+L18 | N18: =SUMPRODUCT($F$33:$F$39/(1+M18)^$C$33:$C$39) | O18: =$D$11/N18 | P18: =$D$11-N18
C19: Money Market / T-Bills | D19: Por definir | E19: Sí | F19: 0.25 | G19: USD | H19: Reinversión | I19: Convención 3 meses | J19: Proxy | L19: 0 | M19: =$D$6+L19 | N19: =SUMPRODUCT($F$33:$F$39/(1+M19)^$C$33:$C$39) | O19: =$D$11/N19 | P19: =$D$11-N19
C20: Beta pasiva S&P 500 | D20: SPY o VOO | E20: No | G20: USD | H20: Renta variable | I20: Estrategia corregida | J20: Core pasivo; no inmuniza educación | L20: 0.01 | M20: =$D$6+L20 | N20: =SUMPRODUCT($F$33:$F$39/(1+M20)^$C$33:$C$39) | O20: =$D$11/N20 | P20: =$D$11-N20
C21: Treasury STRIPS largos | D21: GOVZ (proxy EDV) | E21: Sí | F21: 26.52 | G21: USD | H21: Tasa (alta sensibilidad, sin spread de crédito) | I21: Yahoo Finance (EDV), 10-sep-2026 / '04_Universo_Benchmarks'!J17 | J21: Agregado: faltaba en el listado pese a estar en 04_Universo_Benchmarks y disponible en 05_Datos_Historicos | L21: 0.02 | M21: =$D$6+L21 | N21: =SUMPRODUCT($F$33:$F$39/(1+M21)^$C$33:$C$39) | O21: =$D$11/N21 | P21: =$D$11-N21
C22: Conclusión | D22: Con GOVZ (duración 26,52 años) incorporado al conjunto de instrumentos, la duración máxima disponible (26,52) supera la duración modificada del pasivo (16,5); el calce es factible por duración.
C23: Implicancia | D23: Combinar VCLT, TLH y GOVZ (estrategia barbell) para igualar la duración del pasivo; ver pesos calculados en 09_Optimizador_Cartera.
C24: Restricción | D24: Antes de asignar capital, validar GOVZ como proxy de STRIPS (liquidez, tracking) y fijar un límite de concentración dado su alto riesgo de tasa. | L24: CONTROLES
L25: Control | M25: Resultado | N25: Referencia | O25: Diferencia | P25: Estado
L26: VP educación | M26: =D7 | N26: ='02_TIR_Objetivos'!I7 | O26: =M26-N26 | P26: =IF(ABS(O26)<0.01,"OK","ERROR")
L27: Funding ratio | M27: =D12 | N27: 1 | O27: =M27-N27 | P27: =IF(ABS(O27)<0.01,"OK","ERROR")
L28: Pagos totales | M28: =F40 | N28: ='00_Inputs'!D39 | O28: =M28-N28 | P28: =IF(ABS(O28)<0.01,"OK","ERROR")
L29: Duración positiva | M29: =D9 | N29: 0 | O29: =M29-N29 | P29: =IF(M29>0,"OK","ERROR")
L30: Factibilidad informada | M30: =IF(I9<>"",1,0) | N30: 1 | O30: =M30-N30 | P30: =IF(ABS(O30)<0.01,"OK","ERROR")
C31: CALENDARIO Y DURACIÓN DEL PASIVO
C32: Año | D32: Vicente | E32: Emilia | F32: Pago total | G32: Factor descuento | H32: Valor presente | I32: Año x VP | J32: Convexidad contrib.
C33: 14 | D33: =-'01_Flujos'!F24 | E33: =-'01_Flujos'!G24 | F33: =D33+E33 | G33: =1/(1+$D$6)^C33 | H33: =F33*G33 | I33: =C33*H33 | J33: =C33*(C33+1)*F33/(1+$D$6)^(C33+2)
C34: 15 | D34: =-'01_Flujos'!F25 | E34: =-'01_Flujos'!G25 | F34: =D34+E34 | G34: =1/(1+$D$6)^C34 | H34: =F34*G34 | I34: =C34*H34 | J34: =C34*(C34+1)*F34/(1+$D$6)^(C34+2)
C35: 16 | D35: =-'01_Flujos'!F26 | E35: =-'01_Flujos'!G26 | F35: =D35+E35 | G35: =1/(1+$D$6)^C35 | H35: =F35*G35 | I35: =C35*H35 | J35: =C35*(C35+1)*F35/(1+$D$6)^(C35+2)
C36: 17 | D36: =-'01_Flujos'!F27 | E36: =-'01_Flujos'!G27 | F36: =D36+E36 | G36: =1/(1+$D$6)^C36 | H36: =F36*G36 | I36: =C36*H36 | J36: =C36*(C36+1)*F36/(1+$D$6)^(C36+2)
C37: 18 | D37: =-'01_Flujos'!F28 | E37: =-'01_Flujos'!G28 | F37: =D37+E37 | G37: =1/(1+$D$6)^C37 | H37: =F37*G37 | I37: =C37*H37 | J37: =C37*(C37+1)*F37/(1+$D$6)^(C37+2)
C38: 19 | D38: =-'01_Flujos'!F29 | E38: =-'01_Flujos'!G29 | F38: =D38+E38 | G38: =1/(1+$D$6)^C38 | H38: =F38*G38 | I38: =C38*H38 | J38: =C38*(C38+1)*F38/(1+$D$6)^(C38+2)
C39: 20 | D39: =-'01_Flujos'!F30 | E39: =-'01_Flujos'!G30 | F39: =D39+E39 | G39: =1/(1+$D$6)^C39 | H39: =F39*G39 | I39: =C39*H39 | J39: =C39*(C39+1)*F39/(1+$D$6)^(C39+2)
C40: Total | F40: =SUM(F33:F39) | H40: =SUM(H33:H39) | I40: =SUM(I33:I39) | J40: =SUM(J33:J39)

Sheet 04_Universo_Benchmarks
C2: MODELO NEXUM - UNIVERSO ESTRATÉGICO Y BENCHMARKS
C3: Define las unidades que entrarán al optimizador y su medición. Los pesos todavía no se fijan: serán una salida de Markowitz/Solver.
C5: RESUMEN DEL UNIVERSO | H5: CRITERIO METODOLÓGICO
C6: Sleeves optimizables | D6: =COUNTIF(G15:G22,"Sí") | E6: unidades | F6: Cada fila es una serie de retorno | H6: Unidad de optimización | I6: Sleeve estratégico | K6: Evita mezclar acciones individuales con ETF
C7: Pasivos / core | D7: =COUNTIF(E15:E22,"Pasiva / core") | E7: unidades | F7: ETF o liquidez | H7: Frecuencia objetivo | I7: Mensual | K7: Retornos totales en USD
C8: Activos | D8: =COUNTIF(E15:E22,"Activa") | E8: unidades | F8: Estrategias sistemáticas | H8: ETF pasivos | I8: Total return | K8: Precio ajustado por distribuciones
C9: Elegibles LDI | D9: =COUNTIF(H15:H22,"Sí") | E9: unidades | F9: Tasa, crédito o caja | H9: Estrategias activas | I9: Backtest neto | K9: Serie construida con reglas ex ante
C10: Mayor duración disponible | D10: =MAX(J15:J22) | E10: años | F10: Incluye GOVZ candidato | H10: Pesos | I10: Borrador en 09_Optimizador_Cartera | K10: Sujeto a validar con Solver en Excel; ver limitaciones en esa hoja
C11: Brecha vs. pasivo | D11: =D10-'03_LDI_Educacion'!D9 | E11: años | F11: Máximo activo menos pasivo | H11: Benchmark de política | I11: Dinámico | K11: Suma de pesos finales × benchmarks
C13: 1. UNIVERSO PARA OPTIMIZACIÓN | O13: CONTROLES
C14: ID | D14: Sleeve estratégico | E14: Gestión | F14: Implementación base | G14: Optimizador | H14: LDI | I14: Moneda | J14: Duración | K14: Costo anual | L14: Serie requerida | M14: Estado | O14: Control | P14: Resultado | Q14: Objetivo | R14: Estado
C15: LDI_CORP | D15: Bonos corporativos largos | E15: Pasiva / core | F15: VCLT | G15: Sí | H15: Sí | I15: USD | J15: 13 | L15: TR mensual VCLT | M15: Incluido; duración + spread de crédito | O15: IDs únicos | P15: =IF(AND(COUNTIF($C$15:$C$22,C15)=1,COUNTIF($C$15:$C$22,C16)=1,COUNTIF($C$15:$C$22,C17)=1,COUNTIF($C$15:$C$22,C18)=1,COUNTIF($C$15:$C$22,C19)=1,COUNTIF($C$15:$C$22,C20)=1,COUNTIF($C$15:$C$22,C21)=1,COUNTIF($C$15:$C$22,C22)=1),0,1) | Q15: 0 | R15: =IF(P15=Q15,"OK","REVISAR")
C16: LDI_TSY | D16: Treasuries 10–20 años | E16: Pasiva / core | F16: TLH | G16: Sí | H16: Sí | I16: USD | J16: 11.71 | K16: 0.0015 | L16: TR mensual TLH | M16: Incluido; duración soberana líquida | O16: Benchmark por sleeve | P16: =COUNTBLANK(D27:D34) | Q16: 0 | R16: =IF(P16=Q16,"OK","REVISAR")
C17: LDI_STRIPS | D17: Treasury STRIPS largos | E17: Pasiva / core | F17: GOVZ | G17: Sí | H17: Sí | I17: USD | J17: 26.52 | K17: 0.001 | L17: TR mensual GOVZ | M17: Candidato; fuente oficial | O17: Pesos fijados | P17: 0 | Q17: 0 | R17: =IF(P17=Q17,"OK","REVISAR")
C18: EQ_CORE | D18: Beta pasiva S&P 500 | E18: Pasiva / core | F18: SPY (VOO admisible) | G18: Sí | H18: No | I18: USD | K18: 0.000945 | L18: TR mensual ETF | M18: Fuente oficial SPY | O18: Moneda única | P18: =COUNTIF(I15:I22,"<>USD") | Q18: 0 | R18: =IF(P18=Q18,"OK","REVISAR")
C19: CASH | D19: Liquidez / T-Bills 0–3m | E19: Pasiva / core | F19: SGOV | G19: Sí | H19: Sí | I19: USD | J19: 0.25 | K19: 0.0009 | L19: TR mensual SGOV | M19: Duración proxy | O19: Factibilidad duración | P19: =IF(D11>=0,1,0) | Q19: 1 | R19: =IF(P19=Q19,"OK","REVISAR")
C20: MOM_EQ | D20: Momentum renta variable | E20: Activa | F20: Acciones S&P 500 | G20: Sí | H20: No | I20: USD | L20: Backtest neto estrategia | M20: Reglas por parametrizar | O20: Activos con backtest | P20: =IF(L20="Backtest neto estrategia",1,0)+IF(L21="Backtest neto estrategia",1,0)+IF(L22="Backtest neto estrategia",1,0) | Q20: 3 | R20: =IF(P20=Q20,"OK","REVISAR")
C21: BAB_EQ | D21: Betting Against Beta | E21: Activa | F21: Acciones S&P 500 | G21: Sí | H21: No | I21: USD | L21: Backtest neto estrategia | M21: Beta objetivo pendiente
C22: MOM_CMD | D22: Momentum commodities | E22: Activa | F22: GLD / USO / DBA | G22: Sí | H22: No | I22: USD | L22: Backtest neto estrategia | M22: Universo por cerrar
C25: 2. MAPA DE BENCHMARKS
C26: ID | D26: Benchmark | E26: Versión | F26: Construcción / uso | G26: Rebalance | H26: Proveedor | I26: Retorno | J26: Moneda | K26: Estado | L26: Observación
C27: LDI_CORP | D27: Bloomberg U.S. 10+ Year Corporate Bond Index | E27: Total Return | F27: Referencia del ETF y spread de crédito | G27: Según índice | H27: Bloomberg | I27: Total | J27: USD | K27: Correcto | L27: Usar serie TR, no price return
C28: LDI_TSY | D28: ICE U.S. Treasury 10–20 Year Bond Index | E28: Total Return | F28: Referencia oficial de TLH | G28: Mensual / índice | H28: ICE | I28: Total | J28: USD | K28: Correcto | L28: Consistente con implementación
C29: LDI_STRIPS | D29: ICE BofA Long US Treasury Principal STRIPS Index | E29: Total Return | F29: Referencia oficial de GOVZ | G29: Mensual / índice | H29: ICE BofA | I29: Total | J29: USD | K29: Correcto | L29: Aporta duración al universo
C30: EQ_CORE | D30: S&P 500 Index | E30: Total Return | F30: Beta pasiva de gran capitalización EE.UU. | G30: Índice | H30: S&P DJI | I30: Total | J30: USD | K30: Correcto | L30: Preferir versión TR
C31: CASH | D31: ICE 0–3 Month U.S. Treasury Securities Index | E31: Total Return | F31: Referencia oficial de SGOV | G31: Mensual / índice | H31: ICE | I31: Total | J31: USD | K31: Correcto | L31: Mejor que una tasa fija manual
C32: MOM_EQ | D32: S&P 500 Momentum Index | E32: Total Return | F32: Benchmark estilístico de momentum | G32: Semestral | H32: S&P DJI | I32: Total | J32: USD | K32: Correcto | L32: Comparar además contra S&P 500 TR
C33: BAB_EQ | D33: β objetivo × S&P 500 TR + (1−β) × T-Bill TR | E33: Total Return | F33: Benchmark beta-matched; β fijada ex ante | G33: Por período | H33: Construido | I33: Total | J33: USD | K33: Corregido | L33: No usar 70/30 fijo sin estimar β
C34: MOM_CMD | D34: Bloomberg Commodity Index | E34: Total Return | F34: Solo si el universo es diversificado | G34: Índice | H34: Bloomberg | I34: Total | J34: USD | K34: Condicional | L34: Con GLD/USO/DBA crear mezcla neutral
C37: 3. IMPLEMENTACIÓN ADMISIBLE (NO SON PESOS NI SLEEVES ADICIONALES)
C38: Sleeve | D38: Instrumento | E38: Rol | F38: Tratamiento | G38: ¿Serie separada? | H38: Decisión pendiente | I38: Fuente | J38: Estado | L38: DECISIONES DE ESTA HOJA
C39: EQ_CORE | D39: SPY | E39: Implementación base | F39: ETF S&P 500 | G39: No | H39: Confirmar SPY vs VOO | I39: State Street | J39: Admisible | L39: • VCLT y TLH permanecen simultáneamente como sleeves distintos. • Ambos renuevan sus bonos y mantienen exposición de duración; su liquidez permite rebalancear, no evita una repricing inmediata. • GOVZ queda como candidato para inmunización inicial exacta, sujeto a límites. • SPY/VOO representa un solo sleeve pasivo del S&P 500. • Momentum, BAB y commodities entrarán como series de estrategias. • Los pesos siguen vacíos hasta completar datos, backtests y restricciones.
C40: EQ_CORE | D40: VOO | E40: Alternativa de menor costo | F40: Sustituto, no nueva clase | G40: No | H40: Comparar costos/liquidez | I40: Vanguard | J40: Admisible
C41: MOM_EQ | D41: Acciones S&P 500 | E41: Selección momentum | F41: Constituyentes del backtest | G41: No | H41: Ventana, ranking y número | I41: S&P 500 | J41: Pendiente
C42: BAB_EQ | D42: Acciones S&P 500 | E42: Selección baja beta | F42: Constituyentes del backtest | G42: No | H42: Beta objetivo y apalancamiento | I42: S&P 500 | J42: Pendiente
C43: MOM_CMD | D43: GLD | E43: Oro | F43: Parte del backtest | G43: No | H43: Regla de señal | I43: State Street | J43: Provisional
C44: MOM_CMD | D44: USO | E44: Petróleo | F44: Parte del backtest | G44: No | H44: Riesgo de roll yield | I44: USCF | J44: Provisional
C45: MOM_CMD | D45: DBA | E45: Agricultura | F45: Parte del backtest | G45: No | H45: Regla de señal | I45: Invesco | J45: Provisional
C48: Nota: GOVZ hace factible el objetivo por duración en términos de universo, pero su alta sensibilidad a tasas exige límites de concentración y validación mediante Solver.

Sheet 05_Datos_Historicos
C2: MODELO NEXUM - DATOS HISTÓRICOS Y RETORNOS MENSUALES
C3: Calendario común, fuentes y fórmulas que alimentarán backtests, covarianzas, Markowitz y Solver. Sin pesos de cartera.
C5: PARÁMETROS DEL HISTÓRICO | I5: REGLA DE CONSTRUCCIÓN
C6: Inicio objetivo | D6: 40574 | E6: Mes cierre | F6: Permite más de un ciclo de tasas | I6: 1 | K6: Índices | M6: Priorizar benchmark total return para historia larga
C7: Fin del análisis | D7: 46265 | E7: Mes cierre | F7: Último mes completo anterior al modelo | I7: 2 | K7: ETF | M7: Usar ETF para validar implementación, tracking y costos
C8: Frecuencia | D8: Mensual | F8: Cierre de mes | I8: 3 | K8: Activas | M8: Usar retorno neto del backtest, sin look-ahead bias
C9: Moneda funcional | D9: USD | F9: Sin convertir series USD | I9: 4 | K9: Alineación | M9: Conservar solo meses disponibles para todos los sleeves
C10: Tipo de retorno | D10: Total Return | F10: Incluye distribuciones | I10: 5 | K10: Retorno | M10: R(t)=Nivel(t)/Nivel(t−1)−1
C11: Regla de muestra | D11: Complete case | F11: Mismos meses para todas las series | I11: 6 | K11: Vacíos | M11: No reemplazar datos faltantes por cero
C12: Meses esperados | D12: =(YEAR(D7)-YEAR(D6))*12+MONTH(D7)-MONTH(D6)+1 | E12: observaciones | F12: Incluye mes inicial de niveles | I12: 7 | K12: Rebalanceo | M12: Series activas respetan la frecuencia definida ex ante
C14: 1. MAPA DE SERIES Y COBERTURA | W14: CONTROLES
C15: ID | D15: Sleeve | E15: Serie primaria | F15: Serie de validación | G15: Inicio deseado | H15: Fin deseado | I15: Frecuencia | J15: Retorno | K15: Moneda | L15: Fuente primaria | M15: Nivel cargado | N15: Retornos válidos | O15: Faltantes | P15: Cobertura | Q15: Uso | R15: Estado | S15: Observación | W15: Control | X15: Resultado | Y15: Objetivo | Z15: Estado
C16: LDI_CORP | D16: Bonos corporativos largos | E16: VCLT Adjusted Close | F16: Bloomberg US 10+ Year Corporate TR | G16: =$D$6 | H16: =$D$7 | I16: Mensual | J16: Total | K16: USD | L16: Yahoo Finance, Adj Close, 10-sep-2026 | M16: =COUNT(D$27:D$214) | N16: =MAX(0,M16-1) | O16: =$D$12-M16 | P16: =IF($D$12=0,0,M16/$D$12) | Q16: Markowitz + control | R16: =IF(P16=1,"Completa",IF(M16=0,"Pendiente","Parcial")) | S16: ETF implementable; incluye crédito y gastos | W16: Fechas esperadas | X16: =COUNT(C27:C214) | Y16: =$D$12 | Z16: =IF(X16=Y16,"OK","REVISAR")
C17: LDI_TSY | D17: Treasuries 10–20 años | E17: TLH Adjusted Close | F17: ICE US Treasury 10–20 Year TR | G17: =$D$6 | H17: =$D$7 | I17: Mensual | J17: Total | K17: USD | L17: Yahoo Finance, Adj Close, 10-sep-2026 | M17: =COUNT(E$27:E$214) | N17: =MAX(0,M17-1) | O17: =$D$12-M17 | P17: =IF($D$12=0,0,M17/$D$12) | Q17: Markowitz + control | R17: =IF(P17=1,"Completa",IF(M17=0,"Pendiente","Parcial")) | S17: ETF implementable; Treasury sin spread corporativo | W17: Fechas duplicadas | X17: 0 | Y17: 0 | Z17: =IF(X17=Y17,"OK","REVISAR")
C18: LDI_STRIPS | D18: Treasury STRIPS largos | E18: EDV Adjusted Close (proxy GOVZ) | F18: GOVZ / ICE BofA Principal STRIPS TR | G18: =$D$6 | H18: =$D$7 | I18: Mensual | J18: Total | K18: USD | L18: Yahoo Finance, Adj Close, 10-sep-2026 | M18: =COUNT(F$27:F$214) | N18: =MAX(0,M18-1) | O18: =$D$12-M18 | P18: =IF($D$12=0,0,M18/$D$12) | Q18: Markowitz + control | R18: =IF(P18=1,"Completa",IF(M18=0,"Pendiente","Parcial")) | S18: Proxy larga desde 2011; GOVZ se valida desde 2020 | W18: Series completas | X18: =COUNTIF(R16:R23,"Completa") | Y18: 8 | Z18: =IF(X18=Y18,"OK","REVISAR")
C19: EQ_CORE | D19: Beta pasiva S&P 500 | E19: SPY Adjusted Close | F19: S&P 500 Total Return | G19: =$D$6 | H19: =$D$7 | I19: Mensual | J19: Total | K19: USD | L19: Yahoo Finance, Adj Close, 10-sep-2026 | M19: =COUNT(G$27:G$214) | N19: =MAX(0,M19-1) | O19: =$D$12-M19 | P19: =IF($D$12=0,0,M19/$D$12) | Q19: Markowitz + control | R19: =IF(P19=1,"Completa",IF(M19=0,"Pendiente","Parcial")) | S19: ETF implementable del sleeve pasivo | W19: Ceros usados como faltante | X19: =COUNTIF(D27:K214,0) | Y19: 0 | Z19: =IF(X19=Y19,"OK","REVISAR")
C20: CASH | D20: Liquidez / T-Bills | E20: BIL Adjusted Close (proxy SGOV) | F20: SGOV / ICE 0–3 Month Treasury TR | G20: =$D$6 | H20: =$D$7 | I20: Mensual | J20: Total | K20: USD | L20: Yahoo Finance, Adj Close, 10-sep-2026 | M20: =COUNT(H$27:H$214) | N20: =MAX(0,M20-1) | O20: =$D$12-M20 | P20: =IF($D$12=0,0,M20/$D$12) | Q20: Markowitz + control | R20: =IF(P20=1,"Completa",IF(M20=0,"Pendiente","Parcial")) | S20: Proxy de T-Bills desde 2011; SGOV se valida desde 2020 | W20: Retornos fuera de rango ±50% | X20: =IF(X18<8,0,COUNTIF(N28:U214,">0.5")+COUNTIF(N28:U214,"<-0.5")) | Y20: 0 | Z20: =IF(X20=Y20,"OK","REVISAR")
C21: MOM_EQ | D21: Momentum renta variable | E21: SPMO Adjusted Close (proxy) | F21: S&P 500 Momentum Index TR | G21: =$D$6 | H21: =$D$7 | I21: Mensual | J21: Total | K21: USD | L21: Yahoo Finance / Invesco, 10-sep-2026 | M21: =COUNT(I$27:I$214) | N21: =MAX(0,M21-1) | O21: =$D$12-M21 | P21: =IF($D$12=0,0,M21/$D$12) | Q21: Markowitz + backtest | R21: =IF(P21=1,"Completa",IF(M21=0,"Pendiente","Parcial")) | S21: Proxy provisional; no sustituye selección individual | W21: Apto para Markowitz | X21: =IF(AND(X16=Y16,X17=Y17,X18=Y18,X19=Y19,X20=Y20),1,0) | Y21: 1 | Z21: =IF(X21=Y21,"OK","REVISAR")
C22: BAB_EQ | D22: Betting Against Beta | E22: SPLV Adjusted Close (proxy) | F22: Benchmark beta-matched | G22: =$D$6 | H22: =$D$7 | I22: Mensual | J22: Total | K22: USD | L22: Yahoo Finance / Invesco, 10-sep-2026 | M22: =COUNT(J$27:J$214) | N22: =MAX(0,M22-1) | O22: =$D$12-M22 | P22: =IF($D$12=0,0,M22/$D$12) | Q22: Markowitz + backtest | R22: =IF(P22=1,"Completa",IF(M22=0,"Pendiente","Parcial")) | S22: Baja volatilidad ≠ baja beta; validar beta realizada
C23: MOM_CMD | D23: Momentum commodities | E23: Índice neto Commodity Momentum | F23: Bloomberg Commodity TR | G23: =$D$6 | H23: =$D$7 | I23: Mensual | J23: Total | K23: USD | L23: Modelo Nexum + Yahoo Finance, 10-sep-2026 | M23: =COUNT(K$27:K$214) | N23: =MAX(0,M23-1) | O23: =$D$12-M23 | P23: =IF($D$12=0,0,M23/$D$12) | Q23: Markowitz + backtest | R23: =IF(P23=1,"Completa",IF(M23=0,"Pendiente","Parcial")) | S23: Backtest ETF GLD/USO/DBA; BIL sin señal
W24: ESTADO DE ESTA ETAPA Cargadas 5 exposiciones pasivas con 188 niveles ajustados mensuales cada una. EDV extiende la historia de GOVZ y BIL extiende la de SGOV. Estas proxies son implementables, pero no son idénticas a los ETF finales; se validarán por solapamiento desde 2020. Las tres estrategias activas permanecen pendientes hasta construir backtests sin look-ahead bias. Markowitz continúa bloqueado hasta completar las ocho series.
C25: 2. NIVELES TOTAL RETURN / ÍNDICES (INPUT) | M25: 3. RETORNOS MENSUALES (CÁLCULO)
C26: Fecha | D26: LDI_CORP | E26: LDI_TSY | F26: LDI_STRIPS | G26: EQ_CORE | H26: CASH | I26: MOM_EQ | J26: BAB_EQ | K26: MOM_CMD | M26: Fecha | N26: LDI_CORP | O26: LDI_TSY | P26: LDI_STRIPS | Q26: EQ_CORE | R26: CASH | S26: MOM_EQ | T26: BAB_EQ | U26: MOM_CMD
C27: 40574 | D27: 38.328106 | E27: 73.719078 | F27: 40.941681 | G27: 97.919441 | H27: 73.224716 | K27: ='07_Backtest_CMD'!AL40 | M27: 40574
C28: 40602 | D28: 39.000149 | E28: 74.271912 | F28: 42.048649 | G28: 101.32092 | H28: 73.224716 | K28: ='07_Backtest_CMD'!AL41 | M28: 40602 | N28: =IF(OR(D28="",D27=""),"",D28/D27-1) | O28: =IF(OR(E28="",E27=""),"",E28/E27-1) | P28: =IF(OR(F28="",F27=""),"",F28/F27-1) | Q28: =IF(OR(G28="",G27=""),"",G28/G27-1) | R28: =IF(OR(H28="",H27=""),"",H28/H27-1) | S28: =IF(OR(I28="",I27=""),"",I28/I27-1) | T28: =IF(OR(J28="",J27=""),"",J28/J27-1) | U28: =IF(OR(K28="",K27=""),"",K28/K27-1)
C29: 40633 | D29: 38.754154 | E29: 74.119438 | F29: 41.997406 | G29: 101.33308 | H29: 73.224716 | K29: ='07_Backtest_CMD'!AL42 | M29: 40633 | N29: =IF(OR(D29="",D28=""),"",D29/D28-1) | O29: =IF(OR(E29="",E28=""),"",E29/E28-1) | P29: =IF(OR(F29="",F28=""),"",F29/F28-1) | Q29: =IF(OR(G29="",G28=""),"",G29/G28-1) | R29: =IF(OR(H29="",H28=""),"",H29/H28-1) | S29: =IF(OR(I29="",I28=""),"",I29/I28-1) | T29: =IF(OR(J29="",J28=""),"",J29/J28-1) | U29: =IF(OR(K29="",K28=""),"",K29/K28-1)
C30: 40663 | D30: 39.80669 | E30: 75.548477 | F30: 43.307144 | G30: 104.26781 | H30: 73.224716 | K30: ='07_Backtest_CMD'!AL43 | M30: 40663 | N30: =IF(OR(D30="",D29=""),"",D30/D29-1) | O30: =IF(OR(E30="",E29=""),"",E30/E29-1) | P30: =IF(OR(F30="",F29=""),"",F30/F29-1) | Q30: =IF(OR(G30="",G29=""),"",G30/G29-1) | R30: =IF(OR(H30="",H29=""),"",H30/H29-1) | S30: =IF(OR(I30="",I29=""),"",I30/I29-1) | T30: =IF(OR(J30="",J29=""),"",J30/J29-1) | U30: =IF(OR(K30="",K29=""),"",K30/K29-1)
C31: 40694 | D31: 40.897831 | E31: 77.696457 | F31: 45.788231 | G31: 103.09853 | H31: 73.240692 | J31: 17.846209 | K31: ='07_Backtest_CMD'!AL44 | M31: 40694 | N31: =IF(OR(D31="",D30=""),"",D31/D30-1) | O31: =IF(OR(E31="",E30=""),"",E31/E30-1) | P31: =IF(OR(F31="",F30=""),"",F31/F30-1) | Q31: =IF(OR(G31="",G30=""),"",G31/G30-1) | R31: =IF(OR(H31="",H30=""),"",H31/H30-1) | S31: =IF(OR(I31="",I30=""),"",I31/I30-1) | T31: =IF(OR(J31="",J30=""),"",J31/J30-1) | U31: =IF(OR(K31="",K30=""),"",K31/K30-1)
C32: 40724 | D32: 40.031162 | E32: 76.629753 | F32: 43.800438 | G32: 101.3593 | H32: 73.240692 | J32: 17.638529 | K32: ='07_Backtest_CMD'!AL45 | M32: 40724 | N32: =IF(OR(D32="",D31=""),"",D32/D31-1) | O32: =IF(OR(E32="",E31=""),"",E32/E31-1) | P32: =IF(OR(F32="",F31=""),"",F32/F31-1) | Q32: =IF(OR(G32="",G31=""),"",G32/G31-1) | R32: =IF(OR(H32="",H31=""),"",H32/H31-1) | S32: =IF(OR(I32="",I31=""),"",I32/I31-1) | T32: =IF(OR(J32="",J31=""),"",J32/J31-1) | U32: =IF(OR(K32="",K31=""),"",K32/K31-1)
C33: 40755 | D33: 41.60384 | E33: 79.646957 | F33: 46.425346 | G33: 99.331627 | H33: 73.240692 | J33: 17.226107 | K33: ='07_Backtest_CMD'!AL46 | M33: 40755 | N33: =IF(OR(D33="",D32=""),"",D33/D32-1) | O33: =IF(OR(E33="",E32=""),"",E33/E32-1) | P33: =IF(OR(F33="",F32=""),"",F33/F32-1) | Q33: =IF(OR(G33="",G32=""),"",G33/G32-1) | R33: =IF(OR(H33="",H32=""),"",H33/H32-1) | S33: =IF(OR(I33="",I32=""),"",I33/I32-1) | T33: =IF(OR(J33="",J32=""),"",J33/J32-1) | U33: =IF(OR(K33="",K32=""),"",K33/K32-1)
C34: 40786 | D34: 42.118465 | E34: 84.846062 | F34: 54.025723 | G34: 93.870842 | H34: 73.240692 | J34: 17.238224 | K34: ='07_Backtest_CMD'!AL47 | M34: 40786 | N34: =IF(OR(D34="",D33=""),"",D34/D33-1) | O34: =IF(OR(E34="",E33=""),"",E34/E33-1) | P34: =IF(OR(F34="",F33=""),"",F34/F33-1) | Q34: =IF(OR(G34="",G33=""),"",G34/G33-1) | R34: =IF(OR(H34="",H33=""),"",H34/H33-1) | S34: =IF(OR(I34="",I33=""),"",I34/I33-1) | T34: =IF(OR(J34="",J33=""),"",J34/J33-1) | U34: =IF(OR(K34="",K33=""),"",K34/K33-1)
C35: 40816 | D35: 43.548748 | E35: 89.135994 | F35: 66.864548 | G35: 87.354218 | H35: 73.224716 | J35: 16.868879 | K35: ='07_Backtest_CMD'!AL48 | M35: 40816 | N35: =IF(OR(D35="",D34=""),"",D35/D34-1) | O35: =IF(OR(E35="",E34=""),"",E35/E34-1) | P35: =IF(OR(F35="",F34=""),"",F35/F34-1) | Q35: =IF(OR(G35="",G34=""),"",G35/G34-1) | R35: =IF(OR(H35="",H34=""),"",H35/H34-1) | S35: =IF(OR(I35="",I34=""),"",I35/I34-1) | T35: =IF(OR(J35="",J34=""),"",J35/J34-1) | U35: =IF(OR(K35="",K34=""),"",K35/K34-1)
C36: 40847 | D36: 45.022495 | E36: 87.311516 | F36: 62.399704 | G36: 96.888687 | H36: 73.192772 | J36: 17.872644 | K36: ='07_Backtest_CMD'!AL49 | M36: 40847 | N36: =IF(OR(D36="",D35=""),"",D36/D35-1) | O36: =IF(OR(E36="",E35=""),"",E36/E35-1) | P36: =IF(OR(F36="",F35=""),"",F36/F35-1) | Q36: =IF(OR(G36="",G35=""),"",G36/G35-1) | R36: =IF(OR(H36="",H35=""),"",H36/H35-1) | S36: =IF(OR(I36="",I35=""),"",I36/I35-1) | T36: =IF(OR(J36="",J35=""),"",J36/J35-1) | U36: =IF(OR(K36="",K35=""),"",K36/K35-1)
C37: 40877 | D37: 43.544956 | E37: 88.30101 | F37: 64.55629 | G37: 96.494957 | H37: 73.208733 | J37: 18.059425 | K37: ='07_Backtest_CMD'!AL50 | M37: 40877 | N37: =IF(OR(D37="",D36=""),"",D37/D36-1) | O37: =IF(OR(E37="",E36=""),"",E37/E36-1) | P37: =IF(OR(F37="",F36=""),"",F37/F36-1) | Q37: =IF(OR(G37="",G36=""),"",G37/G36-1) | R37: =IF(OR(H37="",H36=""),"",H37/H36-1) | S37: =IF(OR(I37="",I36=""),"",I37/I36-1) | T37: =IF(OR(J37="",J36=""),"",J37/J36-1) | U37: =IF(OR(K37="",K36=""),"",K37/K36-1)
C38: 40908 | D38: 45.425926 | E38: 90.389778 | F38: 68.059143 | G38: 97.503204 | H38: 73.195953 | J38: 18.622484 | K38: ='07_Backtest_CMD'!AL51 | M38: 40908 | N38: =IF(OR(D38="",D37=""),"",D38/D37-1) | O38: =IF(OR(E38="",E37=""),"",E38/E37-1) | P38: =IF(OR(F38="",F37=""),"",F38/F37-1) | Q38: =IF(OR(G38="",G37=""),"",G38/G37-1) | R38: =IF(OR(H38="",H37=""),"",H38/H37-1) | S38: =IF(OR(I38="",I37=""),"",I38/I37-1) | T38: =IF(OR(J38="",J37=""),"",J38/J37-1) | U38: =IF(OR(K38="",K37=""),"",K38/K37-1)
C39: 40939 | D39: 46.177795 | E39: 90.906479 | F39: 67.021019 | G39: 102.02486 | H39: 73.18 | J39: 18.51972 | K39: ='07_Backtest_CMD'!AL52 | M39: 40939 | N39: =IF(OR(D39="",D38=""),"",D39/D38-1) | O39: =IF(OR(E39="",E38=""),"",E39/E38-1) | P39: =IF(OR(F39="",F38=""),"",F39/F38-1) | Q39: =IF(OR(G39="",G38=""),"",G39/G38-1) | R39: =IF(OR(H39="",H38=""),"",H39/H38-1) | S39: =IF(OR(I39="",I38=""),"",I39/I38-1) | T39: =IF(OR(J39="",J38=""),"",J39/J38-1) | U39: =IF(OR(K39="",K38=""),"",K39/K38-1)
